<?xml version="1.0"?>
<robot name="bee">
<!-- ==================================================================== -->

  <link name="dummy_link">
    <!-- <inertial>
      <mass value="0.0"/>
      <inertia ixx="0.0" ixy="0.0" ixz="0.0" iyy="0.0" iyz="0.0" izz="0.0"/>
    </inertial> -->
  </link>

  <!-- ==================================================================== -->
  <link name="base_link">
    <origin xyz="0 0 0" rpy="0 0 0"/>
    <inertial>
      <mass value="1.4509320"/>
      <inertia ixx="0.02295" ixy="-0.000081038" ixz="0.0000000231" 
         iyy="0.02295" iyz="0.0000000778" 
         izz="0.04539" />
    </inertial>
    <gravity>true</gravity>
    <visual name="base_link_vis">
      <origin xyz="0 0 0" rpy="0 0 0"/>
      <geometry>
        <mesh filename="package://bee/meshes/drone_base.dae" scale="0.01 0.01 0.01"/>
      </geometry>
    </visual>
<!-- ==================================================================== -->
    <collision name="base_link_collision_0">
      <origin xyz="0 0 -0.0" rpy="0 0 0"/>
      <geometry>
         <mesh filename="package://bee/meshes/drone_base.dae" scale="0.01 0.01 0.01"/>
      </geometry>
    </collision>
  </link>
<!-- ==================================================================== -->
  <gazebo reference="base_link">
    <sensor name="imu_sensor" type="imu">
      <always_on>1</always_on>
      <update_rate>10</update_rate>
      <visualize>true</visualize>
      <topic>imu</topic>
      <ignition_frame_id>base_link</ignition_frame_id>
    </sensor>
  </gazebo>
<!-- ==================================================================== -->
    
  <joint name="fixed_joint" type="fixed">
    <parent link="dummy_link"/>
    <child link="base_link"/>
  </joint>
<!-- ==================================================================== -->
<!-- ==================Rotor1===================== -->
<gazebo>
  <link name="rod_1">
        <pose>0.245 0 0.05 0 0 0</pose>
        <inertial>
          <pose>0 0.0 0 0.0 0.0 0.0</pose>
          <inertia>
            <ixx>0.00000001</ixx>
            <ixy>0.0</ixy>
            <ixz>0.0</ixz>
            <iyy>0.00000001</iyy>
            <iyz>0.0</iyz>
            <izz>0.00000001</izz>
          </inertia>
          <mass>0.001</mass>
        </inertial>
      </link>
      <link name="blade_1">
        <pose>0.245 0 0.07 0.0 0 0</pose>
        <inertial>
          <pose>0 0.0 0 0.0 0.0 0.0</pose>
          <inertia>
            <ixx>6e-7</ixx>
            <ixy>-1e-6</ixy>
            <ixz>1.0e-10</ixz>
            <iyy>3e-5</iyy>
            <iyz>0.0</iyz>
            <izz>3e-5</izz>
          </inertia>
          <mass>0.012</mass>
        </inertial>
        <visual name="visual">
          <geometry>
            <mesh>
              <uri>model://home/deen/ros2_ws/src/bee/meshes/propeller_11.75cm.obj</uri>
              <scale>0.01 0.01 0.01</scale>
            </mesh>
          </geometry>
        </visual>
      </link>
      <link name="blade_2">
        <pose>0.245 0 0.07 0.0 0 3.141593</pose>
        <inertial>
          <pose>0 0.0 0 0.0 0.0 0.0</pose>
          <inertia>
            <ixx>6e-7</ixx>
            <ixy>-1e-6</ixy>
            <ixz>1.0e-10</ixz>
            <iyy>3e-5</iyy>
            <iyz>0.0</iyz>
            <izz>3e-5</izz>
          </inertia>
          <mass>0.012</mass>
        </inertial>
      </link>
      <joint name="rod_1_joint" type="revolute">
        <parent>base_link</parent>
        <child>rod_1</child>
        <pose>0.0 0.0 0.0 0.0 0.0 0.0</pose>
        <axis>
          <limit>
            <lower>-1e16</lower>
            <upper>1e16</upper>
          </limit>
          <xyz>0.0 0.0 1.0</xyz>
          <dynamics>
            <damping>0.001</damping>
          </dynamics>
        </axis>
        <physics>
          <ode>
            <cfm_damping>1</cfm_damping>
          </ode>
        </physics>
      </joint>
      <joint name="blade_1_joint" type="fixed">
        <parent>rod_1</parent>
        <child>blade_1</child>
        <pose>0.0 0.0 0.0 0.0 0.0 0.0</pose>
      </joint>
      <joint name="blade_2_joint" type="fixed">
        <parent>rod_1</parent>
        <child>blade_2</child>
        <pose>0.0 0.0 0.0 0.0 0.0 0.0</pose>
      </joint>


      <plugin
        filename="ignition-gazebo-joint-state-publisher-system"
        name="gz::sim::systems::JointStatePublisher"></plugin>

      <plugin
        filename="ignition-gazebo-lift-drag-system"
        name="gz::sim::systems::LiftDrag">
        <a0>0.1</a0>
        <cla>0.1</cla>
        <cda>0.001</cda>
        <cma>0.0</cma>
        <cp>0.0 0.5 0</cp>
        <area>0.0109</area>
        <air_density>1.2041</air_density>
        <forward>1 0 0</forward>
        <upward>0 0 -1</upward>
        <link_name>blade_1</link_name>
      </plugin>
      <plugin
        filename="ignition-gazebo-lift-drag-system"
        name="gz::sim::systems::LiftDrag">
        <a0>0.1</a0>
        <cla>0.1</cla>
        <cda>0.001</cda>
        <cma>0.0</cma>
        <cp>0.0 0.5 0</cp>
        <area>0.0109</area>
        <air_density>1.2041</air_density>
        <forward>1 0 0</forward>
        <upward>0 0 -1</upward>
        <link_name>blade_2</link_name>
      </plugin>
      <plugin
        filename="ignition-gazebo-apply-joint-force-system"
        name="gz::sim::systems::ApplyJointForce">
        <joint_name>rod_1_joint</joint_name>
      </plugin>
  </gazebo>
  <!-- ===========================Rotor 2=========================== -->
  <gazebo>
    <link name="rod_2">
      <pose>-0.245 0 0.05 0 0 0</pose>
      <inertial>
          <pose>0 0.0 0 0.0 0.0 0.0</pose>
          <inertia>
            <ixx>0.00000001</ixx>
            <ixy>0.0</ixy>
            <ixz>0.0</ixz>
            <iyy>0.00000001</iyy>
            <iyz>0.0</iyz>
            <izz>0.00000001</izz>
          </inertia>
          <mass>0.001</mass>
        </inertial>
    </link>

    <link name="blade_3">
      <pose>-0.245 0 0.07 0.0 0 0</pose>
      <inertial>
        <pose>0 0.0 0 0.0 0.0 0.0</pose>
        <inertia>
          <ixx>6e-7</ixx>
          <ixy>-1.6e-6</ixy>
          <ixz>1.0e-10</ixz>
          <iyy>3e-5</iyy>
          <iyz>0.0</iyz>
          <izz>3e-5</izz>
        </inertia>
        <mass>0.012</mass>
      </inertial>
      <visual name="visual">
        <geometry>
          <mesh>
            <uri>model://home/deen/ros2_ws/src/bee/meshes/propeller_11.75cm.obj</uri>
            <scale>0.01 0.01 0.01</scale>
          </mesh>
        </geometry>
      </visual>
    </link>
    <link name="blade_4">
      <pose>-0.245 0 0.07 0.0 0 3.141593</pose>
      <inertial>
        <pose>0 0.0 0 0.0 0.0 0.0</pose>
        <inertia>
          <ixx>6e-7</ixx>
          <ixy>-1.6e-6</ixy>
          <ixz>1.0e-10</ixz>
          <iyy>3e-5</iyy>
          <iyz>0.0</iyz>
          <izz>3e-5</izz>
        </inertia>
        <mass>0.012</mass>
      </inertial>
    </link>

    <joint name="rod_2_joint" type="revolute">
      <parent>base_link</parent>
      <child>rod_2</child>
      <pose>0.0 0.0 0.0 0.0 0.0 0.0</pose>
      <axis>
        <limit>
          <lower>-1e16</lower>
          <upper>1e16</upper>
        </limit>
        <xyz>0.0 0.0 1.0</xyz>
        <dynamics>
          <damping>0.001</damping>
        </dynamics>
      </axis>
      <physics>
        <ode>
          <cfm_damping>1</cfm_damping>
        </ode>
      </physics>
    </joint>
    <joint name="blade_3_joint" type="fixed">
      <parent>rod_2</parent>
      <child>blade_3</child>
      <pose>0.0 0.0 0.0 0.0 0.0 0.0</pose>
    </joint>
    <joint name="blade_4_joint" type="fixed">
      <parent>rod_2</parent>
      <child>blade_4</child>
      <pose>0.0 0.0 0.0 0.0 0.0 0.0</pose>
    </joint>


    <plugin
      filename="ignition-gazebo-joint-state-publisher-system"
      name="gz::sim::systems::JointStatePublisher"></plugin>

    <plugin
      filename="ignition-gazebo-lift-drag-system"
      name="gz::sim::systems::LiftDrag">
      <a0>0.1</a0>
      <cla>0.1</cla>
      <cda>0.001</cda>
      <cma>0.0</cma>
      <cp>0.0 0.5 0</cp>
      <area>0.0109</area>
      <air_density>1.2041</air_density>
      <forward>1 0 0</forward>
      <upward>0 0 -1</upward>
      <link_name>blade_3</link_name>
    </plugin>
    <plugin
      filename="ignition-gazebo-lift-drag-system"
      name="gz::sim::systems::LiftDrag">
      <a0>0.1</a0>
      <cla>0.1</cla>
      <cda>0.001</cda>
      <cma>0.0</cma>
      <cp>0.0 0.5 0</cp>
      <area>0.0109</area>
      <air_density>1.2041</air_density>
      <forward>1 0 0</forward>
      <upward>0 0 -1</upward>
      <link_name>blade_4</link_name>
    </plugin>
    <plugin
      filename="ignition-gazebo-apply-joint-force-system"
      name="gz::sim::systems::ApplyJointForce">
      <joint_name>rod_2_joint</joint_name>
    </plugin>
  </gazebo>
<!-- ======================== Rotor 3 ========================== -->
  <gazebo>
    <link name="rod_3">
      <pose>0.0 0.245 0.05 0 0 0</pose>
      <inertial>
        <pose>0 0.0 0 0.0 0.0 0.0</pose>
        <inertia>
          <ixx>0.00000001</ixx>
          <ixy>0.0</ixy>
          <ixz>0.0</ixz>
          <iyy>0.00000001</iyy>
          <iyz>0.0</iyz>
          <izz>0.00000001</izz>
        </inertia>
        <mass>0.001</mass>
      </inertial>
    </link>

    <link name="blade_5">
      <pose>-0.0 0.245 0.07 0.0 0 0</pose>
      <inertial>
        <pose>0 0.0 0 0.0 0.0 0.0</pose>
        <inertia>
          <ixx>6e-7</ixx>
          <ixy>-1.6e-6</ixy>
          <ixz>1.0e-10</ixz>
          <iyy>3e-5</iyy>
          <iyz>0.0</iyz>
          <izz>3e-5</izz>
        </inertia>
        <mass>0.012</mass>
      </inertial>
      <visual name="visual">
        <geometry>
          <mesh>
            <uri>model://home/deen/ros2_ws/src/bee/meshes/propeller_11.75cm.obj</uri>
            <scale>0.01 0.01 0.01</scale>
          </mesh>
        </geometry>
      </visual>
    </link>
    <link name="blade_6">
      <pose>-0.0 0.245 0.07 0.0 0 3.141593</pose>
      <inertial>
      <pose>0 0.0 0 0.0 0.0 0.0</pose>
      <inertia>
        <ixx>6e-7</ixx>
        <ixy>-1e-6</ixy>
        <ixz>1.0e-10</ixz>
        <iyy>3e-5</iyy>
        <iyz>0.0</iyz>
        <izz>3e-5</izz>
      </inertia>
      <mass>0.012</mass>
    </inertial>
    </link>

    <joint name="rod_3_joint" type="revolute">
      <parent>base_link</parent>
      <child>rod_3</child>
      <pose>0.0 0.0 0.0 0.0 0.0 0.0</pose>
      <axis>
        <limit>
          <lower>-1e16</lower>
          <upper>1e16</upper>
        </limit>
        <xyz>0.0 0.0 -1.0</xyz>
        <dynamics>
          <damping>0.001</damping>
        </dynamics>
      </axis>
      <physics>
        <ode>
          <cfm_damping>1</cfm_damping>
        </ode>
      </physics>
    </joint>
    <joint name="blade_5_joint" type="fixed">
      <parent>rod_3</parent>
      <child>blade_5</child>
      <pose>0.0 0.0 0.0 0.0 0.0 0.0</pose>
    </joint>
    <joint name="blade_6_joint" type="fixed">
      <parent>rod_3</parent>
      <child>blade_6</child>
      <pose>0.0 0.0 0.0 0.0 0.0 0.0</pose>
    </joint>


    <plugin
      filename="ignition-gazebo-joint-state-publisher-system"
      name="gz::sim::systems::JointStatePublisher"></plugin>

    <plugin
      filename="ignition-gazebo-lift-drag-system"
      name="gz::sim::systems::LiftDrag">
      <a0>0.1</a0>
      <cla>0.1</cla>
      <cda>0.001</cda>
      <cma>0.0</cma>
      <cp>0.0 0.5 0</cp>
      <area>0.0109</area>
      <air_density>1.2041</air_density>
      <forward>1 0 0</forward>
      <upward>0 0 1</upward>
      <link_name>blade_5</link_name>
    </plugin>
    <plugin
      filename="ignition-gazebo-lift-drag-system"
      name="gz::sim::systems::LiftDrag">
      <a0>0.1</a0>
      <cla>0.1</cla>
      <cda>0.001</cda>
      <cma>0.0</cma>
      <cp>0.0 0.5 0</cp>
      <area>0.0109</area>
      <air_density>1.2041</air_density>
      <forward>1 0 0</forward>
      <upward>0 0 1</upward>
      <link_name>blade_6</link_name>
    </plugin>
    <plugin
      filename="ignition-gazebo-apply-joint-force-system"
      name="gz::sim::systems::ApplyJointForce">
      <joint_name>rod_3_joint</joint_name>
    </plugin>
  </gazebo>
  <!-- ======================== Rotor 4 ========================== -->
  <gazebo>
    <link name="rod_4">
      <pose>0.0 -0.245 0.05 0 0 0</pose>
      <inertial>
        <pose>0 0.0 0 0.0 0.0 0.0</pose>
        <inertia>
          <ixx>0.00000001</ixx>
          <ixy>0.0</ixy>
          <ixz>0.0</ixz>
          <iyy>0.00000001</iyy>
          <iyz>0.0</iyz>
          <izz>0.00000001</izz>
        </inertia>
        <mass>0.001</mass>
      </inertial>
    </link>

    <link name="blade_7">
      <pose>-0.0 -0.245 0.07 0.0 0 0</pose>
      <inertial>
        <pose>0 0.0 0 0.0 0.0 0.0</pose>
        <inertia>
          <ixx>6e-7</ixx>
          <ixy>-1.6e-6</ixy>
          <ixz>1.0e-10</ixz>
          <iyy>3e-5</iyy>
          <iyz>0.0</iyz>
          <izz>3e-5</izz>
        </inertia>
        <mass>0.012</mass>
      </inertial>
      <visual name="visual">
        <geometry>
          <mesh>
            <uri>model://home/deen/ros2_ws/src/bee/meshes/propeller_11.75cm.obj</uri>
            <scale>0.01 0.01 0.01</scale>
          </mesh>
        </geometry>
      </visual>
    </link>
    <link name="blade_8">
      <pose>0.0 -0.245 0.07 0.0 0 3.141593</pose>
      <inertial>
        <pose>0 0.0 0 0.0 0.0 0.0</pose>
        <inertia>
          <ixx>6e-7</ixx>
          <ixy>-1.6e-6</ixy>
          <ixz>1.0e-10</ixz>
          <iyy>3e-5</iyy>
          <iyz>0.0</iyz>
          <izz>3e-5</izz>
        </inertia>
        <mass>0.012</mass>
      </inertial>
    </link>

    <joint name="rod_4_joint" type="revolute">
      <parent>base_link</parent>
      <child>rod_4</child>
      <pose>0.0 0.0 0.0 0.0 0.0 0.0</pose>
      <axis>
        <limit>
          <lower>-1e16</lower>
          <upper>1e16</upper>
        </limit>
        <xyz>0.0 0.0 -1.0</xyz>
        <dynamics>
          <damping>0.001</damping>
        </dynamics>
      </axis>
      <physics>
        <ode>
          <cfm_damping>1</cfm_damping>
        </ode>
      </physics>
    </joint>
    <joint name="blade_7_joint" type="fixed">
      <parent>rod_4</parent>
      <child>blade_7</child>
      <pose>0.0 0.0 0.0 0.0 0.0 0.0</pose>
    </joint>
    <joint name="blade_8_joint" type="fixed">
      <parent>rod_4</parent>
      <child>blade_8</child>
      <pose>0.0 0.0 0.0 0.0 0.0 0.0</pose>
    </joint>


    <plugin
      filename="ignition-gazebo-joint-state-publisher-system"
      name="gz::sim::systems::JointStatePublisher"></plugin>

    <plugin
      filename="ignition-gazebo-lift-drag-system"
      name="gz::sim::systems::LiftDrag">
      <a0>0.1</a0>
      <cla>0.1</cla>
      <cda>0.001</cda>
      <cma>0.0</cma>
      <cp>0.0 0.5 0</cp>
      <area>0.0109</area>
      <air_density>1.2041</air_density>
      <forward>1 0 0</forward>
      <upward>0 0 1</upward>
      <link_name>blade_7</link_name>
    </plugin>
    <plugin
      filename="ignition-gazebo-lift-drag-system"
      name="gz::sim::systems::LiftDrag">
      <a0>0.1</a0>
      <cla>0.1</cla>
      <cda>0.001</cda>
      <cma>0.0</cma>
      <cp>0.0 0.5 0</cp>
      <area>0.0109</area>
      <air_density>1.2041</air_density>
      <forward>1 0 0</forward>
      <upward>0 0 1</upward>
      <link_name>blade_8</link_name>
    </plugin>
    <plugin
      filename="ignition-gazebo-apply-joint-force-system"
      name="gz::sim::systems::ApplyJointForce">
      <joint_name>rod_4_joint</joint_name>
      <!-- <topic>rod_4</topic> -->
    </plugin>
    <plugin filename="ignition-gazebo-linearbatteryplugin-system"
        name="gz::sim::systems::LinearBatteryPlugin">
        <!--Li-ion battery spec from LIR18650 datasheet-->
        <battery_name>linear_battery</battery_name>
        <voltage>4.2</voltage>
        <open_circuit_voltage_constant_coef>4.2</open_circuit_voltage_constant_coef>
        <open_circuit_voltage_linear_coef>-2.0</open_circuit_voltage_linear_coef>
        <initial_charge>2.5</initial_charge>
        <capacity>2.5 </capacity>
        <resistance>0.07</resistance>
        <smooth_current_tau>2.0</smooth_current_tau>
        <enable_recharge>true</enable_recharge>
        <!-- charging I = c / t, discharging I = P / V,
          charging I should be > discharging I -->
        <charging_time>3.0</charging_time>
        <!-- Consumer-specific -->
        <power_load>2.1</power_load>
        <start_on_motion>true</start_on_motion>
      </plugin>
      <plugin filename="libignition-gazebo6-odometry-publisher-system"
          name="ignition::gazebo::systems::OdometryPublisher">
          <odom_frame>odom</odom_frame>
          <robot_base_frame>base_link</robot_base_frame>
          <odom_topic>odom</odom_topic>
          <tf_topic>/tf</tf_topic>
          <dimensions>3</dimensions>
          <odom_publish_frequency>10</odom_publish_frequency>
      </plugin>
  </gazebo>
</robot>
