<?xml version="1.0"?>
<robot name="drone_sim2_pkg">
<!-- ==================================================================== -->
  <link name="dummy_link">
    <inertial>
      <mass value="0.0"/>
      <inertia ixx="0.0" ixy="0.0" ixz="0.0" iyy="0.0" iyz="0.0" izz="0.0"/>
    </inertial>
  </link>
<!-- ==================================================================== -->
  <joint name="fixed_joint" type="fixed">
    <parent link="dummy_link"/>
    <child link="base_link"/>
  </joint>
<!-- ==================================================================== -->
  <link name="base_link">
    <origin xyz="0 0 10" rpy="0 0 0"/>
    <inertial>
      <mass value="2.0"/>
      <inertia ixx="0.021667" ixy="0.0" ixz="0.0" iyy="0.021667" iyz="0.0" izz="0.041"/>
    </inertial>
    <gravity>true</gravity>
    <visual name="base_link_vis">
      <origin xyz="0 0 .025" rpy="0 0 3.141592654"/>
      <geometry>
        <mesh filename="package://drone_sim2_pkg/meshes/NXP-HGD-CF.dae" />
      </geometry>
    </visual>
<!-- ==================================================================== -->
    <collision name="base_link_collision_0">
      <origin xyz="0 0 -0.115" rpy="0 0 0"/>
      <geometry>
        <box size="0.35355339059327373 0.35355339059327373 0.25"/>
      </geometry>
    </collision>
  </link>
<!-- ==================================================================== -->
  <gazebo reference="base_link">
    <sensor name="imu_sensor" type="imu">
      <always_on>1</always_on>
      <update_rate>10</update_rate>
      <visualize>true</visualize>
      <topic>imu</topic>
      <ignition_frame_id>base_link</ignition_frame_id>
    </sensor>
  </gazebo>
<!-- ==================================================================== -->
  <link name="rotor_0">
    <origin xyz="0.174 -0.174 0.06" rpy="0 0 0"/>
    <inertial>
      <mass value="0.016076923076923075"/>
      <inertia ixx="3.85e-07" ixy="0.0" ixz="0.0" iyy="2.61e-05" iyz="0.0" izz="2.64e-05"/>
    </inertial>
    <visual name="rotor_0_visual">
      <origin xyz="-0.022 -0.175 -0.016" rpy="0 0 0"/>
      <geometry>
        <mesh filename="package://drone_sim2_pkg/meshes/1345_prop_ccw.stl" />
        <scale>0.8461538461538461 0.8461538461538461 0.8461538461538461</scale>
      </geometry>
    </visual>
    <!-- <collision name="rotor_0_collision">
      <origin xyz="0 0 0" rpy="0 0 1.57"/>
      <geometry>
        <box size="0.2792307692307692 0.016923076923076923 0.0008461538461538462"/>
      </geometry>
    </collision> -->
  </link>
<!-- ==================================================================== -->
  <joint name="rotor_0_joint" type="continuous">
    <parent link="base_link"/>
    <child link="rotor_0"/>
    <origin xyz="0.174 -0.174 0.06" rpy="0 0 0"/>
    <axis xyz="0 0 1"/>
  </joint>
<!-- ==================================================================== -->
   <!-- Link definitions -->
  <link name="rod_0">
      <visual>
          <origin xyz="0 0 0" rpy="0 0 0"/> 
          <geometry>
              <box size="0.005 0.005 0.05"/>
          </geometry>
      </visual>
  </link>
<!-- ==================================================================== -->
  <link name="blade_1">
  
    <inertial>
      <origin xyz="0 0 0" rpy="0 0 0"/>
      <mass value="0.001"/>
      <inertia ixx="0.0000465" ixy="0.0" ixz="0.0" iyy="0.0000006" iyz="0.0" izz="0.0000470"/>
    </inertial>
    <collision>
      <origin xyz="0 -0.1 0" rpy="0 0 1.57"/>
      <geometry>
        <box size="0.20 0.017 0.0008"/>
      </geometry>
    </collision>
  </link>
<!-- ==================================================================== -->
  <link name="blade_2">
    <inertial>
      <origin xyz="0 0 0" rpy="0 0 0"/>
      <mass value="0.01"/>
      <inertia ixx="0.0000465" ixy="0.0" ixz="0.0" iyy="0.0000006" iyz="0.0" izz="0.0000470"/>
    </inertial>
    <collision>
      <origin xyz="0 0 1.5" rpy="0 0 3.141593"/>
      <geometry>
        <box size="0.2 1.0 0.01"/>
      </geometry>
    </collision>
  </link>
<!-- ==================================================================== -->
  <!-- Joint definitions -->
  <joint name="rod_0_joint" type="revolute">
      <parent link="base_link"/>
      <child link="rod_0"/>
      <origin xyz="0.18 -0.174 0.06" rpy="0 0 0"/>
      <axis xyz="0.0 0.0 -1.0"/>
      <limit lower="-1.0" upper="1.0" effort="100" velocity="10"/> <!-- Adjusted limits -->
      <dynamics damping="0.0001"/>
  </joint>

<!-- ==================================================================== -->
  <joint name="blade_1_joint" type="fixed">
    <parent link="rod_0"/>
    <child link="blade_1"/>
    <origin xyz="0.0 0.0 0.0" rpy="0.0 0.0 0.0"/>
  </joint>
<!-- ==================================================================== -->
  <joint name="blade_2_joint" type="fixed">
    <parent link="rod_0"/>
    <child link="blade_2"/>
    <origin xyz="0.0 0.0 0.0" rpy="0.0 0.0 0.0"/>
  </joint>
<!-- ............................................................................. -->
  <!-- Rotor 1 -->
  <link name="rotor_1">
    <origin xyz="-0.174 0.174 0.06" rpy="0 0 0"/>
    <inertial>
      <mass value="0.016"/>
      <inertia ixx="3.85e-07" ixy="0.0" ixz="0.0" iyy="2.61e-05" iyz="0.0" izz="2.64e-05"/>
    </inertial>
    <visual name="rotor_1_visual">
      <origin xyz="-0.022 -0.175 -0.016" rpy="0 0 0"/>
      <geometry>
        <mesh filename="package://drone_sim2_pkg/meshes/1345_prop_ccw.stl"/>
        <scale>0.846 0.846 0.846</scale>
      </geometry>
    </visual>
    <collision name="rotor_1_collision">
      <origin xyz="0 0 0" rpy="0 0 1.57"/>
      <geometry>
        <box size="0.279 0.016 0.000846"/>
      </geometry>
    </collision>
  </link>
<!-- ==================================================================== -->
  <joint name="rotor_1_joint" type="continuous">
    <parent link="base_link"/>
    <child link="rotor_1"/>
    <origin xyz="-0.174 0.174 0.06" rpy="0 0 0"/>
    <axis xyz="0 0 1"/>
  </joint>
<!-- ==================================================================== -->
  <!-- Rotor 2 -->
  <link name="rotor_2">
    <origin xyz="0.174 0.174 0.06" rpy="0 0 0"/>
    <inertial>
      <mass value="0.016"/>
      <inertia ixx="3.85e-07" ixy="0.0" ixz="0.0" iyy="2.61e-05" iyz="0.0" izz="2.64e-05"/>
    </inertial>
    <visual name="rotor_2_visual">
      <origin xyz="-0.022 -0.175 -0.016" rpy="0 0 0"/>
      <geometry>
        <mesh filename="package://drone_sim2_pkg/meshes/1345_prop_cw.stl"/>
        <scale>0.846 0.846 0.846</scale>
      </geometry>
    </visual>
    <collision name="rotor_2_collision">
      <origin xyz="0 0 0" rpy="0 0 1.57"/>
      <geometry>
        <box size="0.279 0.016 0.000846"/>
      </geometry>
    </collision>
  </link>
<!-- ==================================================================== -->
  <joint name="rotor_2_joint" type="continuous">
    <parent link="base_link"/>
    <child link="rotor_2"/>
    <origin xyz="0.174 0.174 0.06" rpy="0 0 0"/>
    <axis xyz="0 0 1"/>
  </joint>
<!-- ==================================================================== -->
  <!-- Rotor 3 -->
  <link name="rotor_3">
    <origin xyz="-0.174 -0.174 0.06" rpy="0 0 0"/>
    <inertial>
      <mass value="0.016"/>
      <inertia ixx="3.85e-07" ixy="0.0" ixz="0.0" iyy="2.61e-05" iyz="0.0" izz="2.64e-05"/>
    </inertial>
    <visual name="rotor_3_visual">
      <origin xyz="-0.022 -0.175 -0.016" rpy="0 0 0"/>
      <geometry>
        <mesh filename="package://drone_sim2_pkg/meshes/1345_prop_cw.stl"/>
        <scale>0.846 0.846 0.846</scale>
      </geometry>
    </visual>
    <collision name="rotor_3_collision">
      <origin xyz="0 0 0" rpy="0 0 1.57"/>
      <geometry>
        <box size="0.279 0.016 0.000846"/>
      </geometry>
    </collision>
  </link>
<!-- ==================================================================== -->
  <joint name="rotor_3_joint" type="continuous">
    <parent link="base_link"/>
    <child link="rotor_3"/>
    <origin xyz="-0.174 -0.174 0.06" rpy="0 0 0"/>
    <axis xyz="0 0 1"/>
  </joint>
  <!-- ==================================================================== -->
<!-- ..................GAZEBO SENSORS AND PLUGINS ............................................. -->
  <gazebo>
        <plugin filename="ignition-gazebo-sensors-system" name="ignition::gazebo::systems::Sensors">
            <render_engine>ogre2</render_engine>
        </plugin>

        <plugin filename="ignition-gazebo-imu-system" name="ignition::gazebo::systems::Imu">
        </plugin>

        <plugin filename="ignition-gazebo-joint-state-publisher-system" name="ignition::gazebo::systems::JointStatePublisher">
        </plugin>
        <plugin
        filename="ignition-gazebo-scene-broadcaster-system"
        name="gz::sim::systems::SceneBroadcaster">
        </plugin>
        <plugin
        filename="ignition-gazebo-user-commands-system"
        name="gz::sim::systems::UserCommands">
        </plugin>
        <plugin
          filename="ignition-gazebo-contact-system"
          name="gz::sim::systems::Contact">
        </plugin>

        <plugin filename="libignition-gazebo6-odometry-publisher-system"
            name="ignition::gazebo::systems::OdometryPublisher">
            <odom_frame>odom</odom_frame>
            <robot_base_frame>base_link</robot_base_frame>
            <odom_topic>odom</odom_topic>
            <tf_topic>/tf</tf_topic>
            <dimensions>3</dimensions>
            <odom_publish_frequency>10</odom_publish_frequency>
        </plugin>
  </gazebo>
  <!-- ==================================================================== -->
</robot>
